{"schemaVersion":{"patch":0,"minor":3,"major":0},"hierarchy":{"paths":[["doc:\/\/co.pointfree.VaporRouting\/documentation\/AsyncKit","doc:\/\/co.pointfree.VaporRouting\/documentation\/AsyncKit\/EventLoopFutureQueue","doc:\/\/co.pointfree.VaporRouting\/documentation\/AsyncKit\/EventLoopFutureQueue\/ContinueError"]]},"variants":[{"traits":[{"interfaceLanguage":"swift"}],"paths":["\/documentation\/asynckit\/eventloopfuturequeue\/continueerror\/previoussuccess"]}],"metadata":{"modules":[{"name":"AsyncKit"}],"role":"symbol","roleHeading":"Case","symbolKind":"case","externalID":"s:8AsyncKit20EventLoopFutureQueueC13ContinueErrorO15previousSuccessyA2EmF","title":"EventLoopFutureQueue.ContinueError.previousSuccess","fragments":[{"kind":"keyword","text":"case"},{"kind":"text","text":" "},{"kind":"identifier","text":"previousSuccess"}]},"identifier":{"interfaceLanguage":"swift","url":"doc:\/\/co.pointfree.VaporRouting\/documentation\/AsyncKit\/EventLoopFutureQueue\/ContinueError\/previousSuccess"},"kind":"symbol","sections":[],"primaryContentSections":[{"declarations":[{"languages":["swift"],"platforms":["Linux"],"tokens":[{"text":"case","kind":"keyword"},{"text":" ","kind":"text"},{"text":"previousSuccess","kind":"identifier"}]}],"kind":"declarations"}],"abstract":[{"type":"text","text":"A previous future succeeded, which we don’t desire."}],"references":{"doc://co.pointfree.VaporRouting/documentation/AsyncKit":{"title":"AsyncKit","url":"\/documentation\/asynckit","identifier":"doc:\/\/co.pointfree.VaporRouting\/documentation\/AsyncKit","abstract":[],"type":"topic","kind":"symbol","role":"collection"},"doc://co.pointfree.VaporRouting/documentation/AsyncKit/EventLoopFutureQueue":{"role":"symbol","abstract":[{"type":"text","text":"Allows you to queue closures that produce an "},{"code":"EventLoopFuture","type":"codeVoice"},{"type":"text","text":", so each future only gets run if the previous ones complete, succeed, or fail."}],"navigatorTitle":[{"kind":"identifier","text":"EventLoopFutureQueue"}],"kind":"symbol","title":"EventLoopFutureQueue","identifier":"doc:\/\/co.pointfree.VaporRouting\/documentation\/AsyncKit\/EventLoopFutureQueue","url":"\/documentation\/asynckit\/eventloopfuturequeue","fragments":[{"kind":"keyword","text":"class"},{"kind":"text","text":" "},{"kind":"identifier","text":"EventLoopFutureQueue"}],"type":"topic"},"doc://co.pointfree.VaporRouting/documentation/AsyncKit/EventLoopFutureQueue/ContinueError":{"kind":"symbol","identifier":"doc:\/\/co.pointfree.VaporRouting\/documentation\/AsyncKit\/EventLoopFutureQueue\/ContinueError","url":"\/documentation\/asynckit\/eventloopfuturequeue\/continueerror","type":"topic","navigatorTitle":[{"text":"ContinueError","kind":"identifier"}],"role":"symbol","abstract":[{"type":"text","text":"Errors that get propogated based on a future’s completion status and the next appended closure’s continuation condition."}],"fragments":[{"kind":"keyword","text":"enum"},{"kind":"text","text":" "},{"kind":"identifier","text":"ContinueError"}],"title":"EventLoopFutureQueue.ContinueError"},"doc://co.pointfree.VaporRouting/documentation/AsyncKit/EventLoopFutureQueue/ContinueError/previousSuccess":{"title":"EventLoopFutureQueue.ContinueError.previousSuccess","role":"symbol","abstract":[{"text":"A previous future succeeded, which we don’t desire.","type":"text"}],"identifier":"doc:\/\/co.pointfree.VaporRouting\/documentation\/AsyncKit\/EventLoopFutureQueue\/ContinueError\/previousSuccess","kind":"symbol","url":"\/documentation\/asynckit\/eventloopfuturequeue\/continueerror\/previoussuccess","fragments":[{"kind":"keyword","text":"case"},{"kind":"text","text":" "},{"kind":"identifier","text":"previousSuccess"}],"type":"topic"}}}